<?xml version="1.0" ?>
<robot name="assem" xmlns:xacro="http://www.ros.org/wiki/xacro">

<xacro:include filename="$(find assem_description)/urdf/materials.xacro" />
<xacro:include filename="$(find assem_description)/urdf/assem.trans" />
<link name="base_link">
  <inertial>
    <origin xyz="-0.008382264142625067 -1.4798434925308436e-05 0.030113658418836745" rpy="0 0 0"/>
    <mass value="10.123728045116188"/>
    <inertia ixx="0.03254" iyy="0.280159" izz="0.3037" ixy="-3.1e-05" iyz="-1e-06" ixz="0.001839"/>
  </inertial>
  <visual>
    <origin xyz="0 0 0" rpy="0 0 0"/>
    <geometry>
      <mesh filename="file://$(find robot_description)/meshes/base_link.stl" scale="0.001 0.001 0.001"/>
    </geometry>
    <material name="steel_satin"/>
  </visual>
  <collision>
    <origin xyz="0 0 0" rpy="0 0 0"/>
    <geometry>
      <mesh filename="file://$(find robot_description)/meshes/base_link.stl" scale="0.001 0.001 0.001"/>
    </geometry>
  </collision>
</link>

<link name="Right_Front_Leg_Mount_v1_1">
  <inertial>
    <origin xyz="0.03322621293445238 0.004607470996659868 0.011279980581351271" rpy="0 0 0"/>
    <mass value="0.791396210786452"/>
    <inertia ixx="0.000288" iyy="0.000453" izz="0.000409" ixy="1.4e-05" iyz="-6e-06" ixz="-6e-06"/>
  </inertial>
  <visual>
    <origin xyz="-0.1184 -0.076 -0.0196" rpy="0 0 0"/>
    <geometry>
      <mesh filename="file://$(find robot_description)/meshes/Right_Front_Leg_Mount_v1_1.stl" scale="0.001 0.001 0.001"/>
    </geometry>
    <material name="steel_satin"/>
  </visual>
  <collision>
    <origin xyz="-0.1184 -0.076 -0.0196" rpy="0 0 0"/>
    <geometry>
      <mesh filename="file://$(find robot_description)/meshes/Right_Front_Leg_Mount_v1_1.stl" scale="0.001 0.001 0.001"/>
    </geometry>
  </collision>
</link>

<link name="Right_Back_Leg_Mount_v1_1">
  <inertial>
    <origin xyz="-0.03453360704195005 0.004633032360894143 0.011213744397462203" rpy="0 0 0"/>
    <mass value="0.7913962107864516"/>
    <inertia ixx="0.000288" iyy="0.000458" izz="0.000413" ixy="1.2e-05" iyz="-6e-06" ixz="8e-06"/>
  </inertial>
  <visual>
    <origin xyz="0.1184 -0.076 -0.0196" rpy="0 0 0"/>
    <geometry>
      <mesh filename="file://$(find robot_description)/meshes/Right_Back_Leg_Mount_v1_1.stl" scale="0.001 0.001 0.001"/>
    </geometry>
    <material name="steel_satin"/>
  </visual>
  <collision>
    <origin xyz="0.1184 -0.076 -0.0196" rpy="0 0 0"/>
    <geometry>
      <mesh filename="file://$(find robot_description)/meshes/Right_Back_Leg_Mount_v1_1.stl" scale="0.001 0.001 0.001"/>
    </geometry>
  </collision>
</link>

<link name="Left_Back_Leg_Mount_v1_1">
  <inertial>
    <origin xyz="-0.03453360706419445 -0.004633032653077587 0.011213744349241432" rpy="0 0 0"/>
    <mass value="0.7913962228945977"/>
    <inertia ixx="0.000288" iyy="0.000458" izz="0.000413" ixy="-1.2e-05" iyz="6e-06" ixz="8e-06"/>
  </inertial>
  <visual>
    <origin xyz="0.1184 0.076 -0.0196" rpy="0 0 0"/>
    <geometry>
      <mesh filename="file://$(find robot_description)/meshes/Left_Back_Leg_Mount_v1_1.stl" scale="0.001 0.001 0.001"/>
    </geometry>
    <material name="steel_satin"/>
  </visual>
  <collision>
    <origin xyz="0.1184 0.076 -0.0196" rpy="0 0 0"/>
    <geometry>
      <mesh filename="file://$(find robot_description)/meshes/Left_Back_Leg_Mount_v1_1.stl" scale="0.001 0.001 0.001"/>
    </geometry>
  </collision>
</link>

<link name="Left_Front_Leg_Mount_v1_1">
  <inertial>
    <origin xyz="0.033226212974938135 -0.004607471288838219 0.011279980533589536" rpy="0 0 0"/>
    <mass value="0.791396222894598"/>
    <inertia ixx="0.000288" iyy="0.000453" izz="0.000409" ixy="-1.4e-05" iyz="6e-06" ixz="-6e-06"/>
  </inertial>
  <visual>
    <origin xyz="-0.1184 0.076 -0.0196" rpy="0 0 0"/>
    <geometry>
      <mesh filename="file://$(find robot_description)/meshes/Left_Front_Leg_Mount_v1_1.stl" scale="0.001 0.001 0.001"/>
    </geometry>
    <material name="steel_satin"/>
  </visual>
  <collision>
    <origin xyz="-0.1184 0.076 -0.0196" rpy="0 0 0"/>
    <geometry>
      <mesh filename="file://$(find robot_description)/meshes/Left_Front_Leg_Mount_v1_1.stl" scale="0.001 0.001 0.001"/>
    </geometry>
  </collision>
</link>

<link name="Servo_Horn_v3_1">
  <inertial>
    <origin xyz="0.00849626146165297 -2.908683761748687e-05 -1.6025929275784168e-06" rpy="0 0 0"/>
    <mass value="0.010282942996218928"/>
    <inertia ixx="0.0" iyy="1e-06" izz="1e-06" ixy="-0.0" iyz="0.0" ixz="0.0"/>
  </inertial>
  <visual>
    <origin xyz="-0.164597 -0.103749 -0.038258" rpy="0 0 0"/>
    <geometry>
      <mesh filename="file://$(find robot_description)/meshes/Servo_Horn_v3_1.stl" scale="0.001 0.001 0.001"/>
    </geometry>
    <material name="steel_satin"/>
  </visual>
  <collision>
    <origin xyz="-0.164597 -0.103749 -0.038258" rpy="0 0 0"/>
    <geometry>
      <mesh filename="file://$(find robot_description)/meshes/Servo_Horn_v3_1.stl" scale="0.001 0.001 0.001"/>
    </geometry>
  </collision>
</link>

<link name="Servo_Horn_v3_2">
  <inertial>
    <origin xyz="-0.008496002222424276 -2.9086837616723593e-05 1.9981492505212473e-06" rpy="0 0 0"/>
    <mass value="0.010282942996218928"/>
    <inertia ixx="0.0" iyy="1e-06" izz="1e-06" ixy="0.0" iyz="-0.0" ixz="0.0"/>
  </inertial>
  <visual>
    <origin xyz="-0.143947 -0.103749 -0.017258" rpy="0 0 0"/>
    <geometry>
      <mesh filename="file://$(find robot_description)/meshes/Servo_Horn_v3_2.stl" scale="0.001 0.001 0.001"/>
    </geometry>
    <material name="steel_satin"/>
  </visual>
  <collision>
    <origin xyz="-0.143947 -0.103749 -0.017258" rpy="0 0 0"/>
    <geometry>
      <mesh filename="file://$(find robot_description)/meshes/Servo_Horn_v3_2.stl" scale="0.001 0.001 0.001"/>
    </geometry>
  </collision>
</link>

<link name="Servo_Horn_v3_4">
  <inertial>
    <origin xyz="0.008495912831059382 -2.9238910956921882e-05 -1.8426360164636169e-06" rpy="0 0 0"/>
    <mass value="0.010282942996218928"/>
    <inertia ixx="0.0" iyy="1e-06" izz="1e-06" ixy="-0.0" iyz="0.0" ixz="0.0"/>
  </inertial>
  <visual>
    <origin xyz="0.144387 -0.103775 -0.038162" rpy="0 0 0"/>
    <geometry>
      <mesh filename="file://$(find robot_description)/meshes/Servo_Horn_v3_4.stl" scale="0.001 0.001 0.001"/>
    </geometry>
    <material name="steel_satin"/>
  </visual>
  <collision>
    <origin xyz="0.144387 -0.103775 -0.038162" rpy="0 0 0"/>
    <geometry>
      <mesh filename="file://$(find robot_description)/meshes/Servo_Horn_v3_4.stl" scale="0.001 0.001 0.001"/>
    </geometry>
  </collision>
</link>

<link name="Servo_Horn_v3_3">
  <inertial>
    <origin xyz="-0.008496349973848794 -2.923891095629738e-05 1.7582700742799218e-06" rpy="0 0 0"/>
    <mass value="0.010282942996218928"/>
    <inertia ixx="0.0" iyy="1e-06" izz="1e-06" ixy="0.0" iyz="-0.0" ixz="0.0"/>
  </inertial>
  <visual>
    <origin xyz="0.164387 -0.103775 -0.017162" rpy="0 0 0"/>
    <geometry>
      <mesh filename="file://$(find robot_description)/meshes/Servo_Horn_v3_3.stl" scale="0.001 0.001 0.001"/>
    </geometry>
    <material name="steel_satin"/>
  </visual>
  <collision>
    <origin xyz="0.164387 -0.103775 -0.017162" rpy="0 0 0"/>
    <geometry>
      <mesh filename="file://$(find robot_description)/meshes/Servo_Horn_v3_3.stl" scale="0.001 0.001 0.001"/>
    </geometry>
  </collision>
</link>

<link name="Servo_Horn_v3_5">
  <inertial>
    <origin xyz="0.008496261461652804 2.9086837618014227e-05 1.998089645890988e-06" rpy="0 0 0"/>
    <mass value="0.010282942996218928"/>
    <inertia ixx="0.0" iyy="1e-06" izz="1e-06" ixy="0.0" iyz="0.0" ixz="-0.0"/>
  </inertial>
  <visual>
    <origin xyz="-0.164597 0.103749 -0.038258" rpy="0 0 0"/>
    <geometry>
      <mesh filename="file://$(find robot_description)/meshes/Servo_Horn_v3_5.stl" scale="0.001 0.001 0.001"/>
    </geometry>
    <material name="steel_satin"/>
  </visual>
  <collision>
    <origin xyz="-0.164597 0.103749 -0.038258" rpy="0 0 0"/>
    <geometry>
      <mesh filename="file://$(find robot_description)/meshes/Servo_Horn_v3_5.stl" scale="0.001 0.001 0.001"/>
    </geometry>
  </collision>
</link>

<link name="Servo_Horn_v3_8">
  <inertial>
    <origin xyz="-0.008496002222424415 2.9086837617570138e-05 -1.602533322913463e-06" rpy="0 0 0"/>
    <mass value="0.010282942996218928"/>
    <inertia ixx="0.0" iyy="1e-06" izz="1e-06" ixy="-0.0" iyz="-0.0" ixz="-0.0"/>
  </inertial>
  <visual>
    <origin xyz="-0.143947 0.103749 -0.017258" rpy="0 0 0"/>
    <geometry>
      <mesh filename="file://$(find robot_description)/meshes/Servo_Horn_v3_8.stl" scale="0.001 0.001 0.001"/>
    </geometry>
    <material name="steel_satin"/>
  </visual>
  <collision>
    <origin xyz="-0.143947 0.103749 -0.017258" rpy="0 0 0"/>
    <geometry>
      <mesh filename="file://$(find robot_description)/meshes/Servo_Horn_v3_8.stl" scale="0.001 0.001 0.001"/>
    </geometry>
  </collision>
</link>

<link name="Servo_Horn_v3_7">
  <inertial>
    <origin xyz="0.008495912831059105 2.923891095736597e-05 1.7580465570474213e-06" rpy="0 0 0"/>
    <mass value="0.010282942996218928"/>
    <inertia ixx="0.0" iyy="1e-06" izz="1e-06" ixy="0.0" iyz="0.0" ixz="-0.0"/>
  </inertial>
  <visual>
    <origin xyz="0.144387 0.103775 -0.038162" rpy="0 0 0"/>
    <geometry>
      <mesh filename="file://$(find robot_description)/meshes/Servo_Horn_v3_7.stl" scale="0.001 0.001 0.001"/>
    </geometry>
    <material name="steel_satin"/>
  </visual>
  <collision>
    <origin xyz="0.144387 0.103775 -0.038162" rpy="0 0 0"/>
    <geometry>
      <mesh filename="file://$(find robot_description)/meshes/Servo_Horn_v3_7.stl" scale="0.001 0.001 0.001"/>
    </geometry>
  </collision>
</link>

<link name="Servo_Horn_v3_6">
  <inertial>
    <origin xyz="-0.008496349973849043 2.923891095668596e-05 -1.8424124992970359e-06" rpy="0 0 0"/>
    <mass value="0.010282942996218928"/>
    <inertia ixx="0.0" iyy="1e-06" izz="1e-06" ixy="-0.0" iyz="-0.0" ixz="-0.0"/>
  </inertial>
  <visual>
    <origin xyz="0.164387 0.103775 -0.017162" rpy="0 0 0"/>
    <geometry>
      <mesh filename="file://$(find robot_description)/meshes/Servo_Horn_v3_6.stl" scale="0.001 0.001 0.001"/>
    </geometry>
    <material name="steel_satin"/>
  </visual>
  <collision>
    <origin xyz="0.164387 0.103775 -0.017162" rpy="0 0 0"/>
    <geometry>
      <mesh filename="file://$(find robot_description)/meshes/Servo_Horn_v3_6.stl" scale="0.001 0.001 0.001"/>
    </geometry>
  </collision>
</link>

<link name="Left_Link_v4_1">
  <inertial>
    <origin xyz="0.005235109006971023 -0.0028149971111056937 -0.05611727896629981" rpy="0 0 0"/>
    <mass value="0.12677989413662727"/>
    <inertia ixx="0.000135" iyy="0.000137" izz="6e-06" ixy="-0.0" iyz="-1e-06" ixz="1e-05"/>
  </inertial>
  <visual>
    <origin xyz="0.165037 -0.115355 -0.017162" rpy="0 0 0"/>
    <geometry>
      <mesh filename="file://$(find robot_description)/meshes/Left_Link_v4_1.stl" scale="0.001 0.001 0.001"/>
    </geometry>
    <material name="steel_satin"/>
  </visual>
  <collision>
    <origin xyz="0.165037 -0.115355 -0.017162" rpy="0 0 0"/>
    <geometry>
      <mesh filename="file://$(find robot_description)/meshes/Left_Link_v4_1.stl" scale="0.001 0.001 0.001"/>
    </geometry>
  </collision>
</link>

<link name="Foot_v3_1">
  <inertial>
    <origin xyz="0.0031275273896734235 -0.005052218921323931 -0.06122868364490067" rpy="0 0 0"/>
    <mass value="0.31314451205821014"/>
    <inertia ixx="0.000443" iyy="0.000438" izz="2.5e-05" ixy="-0.0" iyz="0.0" ixz="1e-06"/>
  </inertial>
  <visual>
    <origin xyz="0.162704 -0.115355 0.088726" rpy="0 0 0"/>
    <geometry>
      <mesh filename="file://$(find robot_description)/meshes/Foot_v3_1.stl" scale="0.001 0.001 0.001"/>
    </geometry>
    <material name="steel_satin"/>
  </visual>
  <collision>
    <origin xyz="0.162704 -0.115355 0.088726" rpy="0 0 0"/>
    <geometry>
      <mesh filename="file://$(find robot_description)/meshes/Foot_v3_1.stl" scale="0.001 0.001 0.001"/>
    </geometry>
  </collision>
</link>

<link name="Left_Link_v4_2">
  <inertial>
    <origin xyz="0.005235457637564361 -0.0028148450377657175 -0.056117038923210835" rpy="0 0 0"/>
    <mass value="0.12677989413662727"/>
    <inertia ixx="0.000135" iyy="0.000137" izz="6e-06" ixy="-0.0" iyz="-1e-06" ixz="1e-05"/>
  </inertial>
  <visual>
    <origin xyz="-0.143797 -0.115329 -0.017258" rpy="0 0 0"/>
    <geometry>
      <mesh filename="file://$(find robot_description)/meshes/Left_Link_v4_2.stl" scale="0.001 0.001 0.001"/>
    </geometry>
    <material name="steel_satin"/>
  </visual>
  <collision>
    <origin xyz="-0.143797 -0.115329 -0.017258" rpy="0 0 0"/>
    <geometry>
      <mesh filename="file://$(find robot_description)/meshes/Left_Link_v4_2.stl" scale="0.001 0.001 0.001"/>
    </geometry>
  </collision>
</link>

<link name="Component1_Mirror___4__1">
  <inertial>
    <origin xyz="0.005597894046904056 0.002814845037766786 -0.05642367984565573" rpy="0 0 0"/>
    <mass value="0.1267798941366273"/>
    <inertia ixx="0.000135" iyy="0.000137" izz="6e-06" ixy="0.0" iyz="1e-06" ixz="1e-05"/>
  </inertial>
  <visual>
    <origin xyz="-0.143797 0.115329 -0.017258" rpy="0 0 0"/>
    <geometry>
      <mesh filename="file://$(find robot_description)/meshes/Component1_Mirror___4__1.stl" scale="0.001 0.001 0.001"/>
    </geometry>
    <material name="steel_satin"/>
  </visual>
  <collision>
    <origin xyz="-0.143797 0.115329 -0.017258" rpy="0 0 0"/>
    <geometry>
      <mesh filename="file://$(find robot_description)/meshes/Component1_Mirror___4__1.stl" scale="0.001 0.001 0.001"/>
    </geometry>
  </collision>
</link>

<link name="Component1_Mirror___4__2">
  <inertial>
    <origin xyz="0.005235109006970551 0.0028149971111054717 -0.05611727896629981" rpy="0 0 0"/>
    <mass value="0.1267798941366273"/>
    <inertia ixx="0.000135" iyy="0.000137" izz="6e-06" ixy="0.0" iyz="1e-06" ixz="1e-05"/>
  </inertial>
  <visual>
    <origin xyz="0.165037 0.115355 -0.017162" rpy="0 0 0"/>
    <geometry>
      <mesh filename="file://$(find robot_description)/meshes/Component1_Mirror___4__2.stl" scale="0.001 0.001 0.001"/>
    </geometry>
    <material name="steel_satin"/>
  </visual>
  <collision>
    <origin xyz="0.165037 0.115355 -0.017162" rpy="0 0 0"/>
    <geometry>
      <mesh filename="file://$(find robot_description)/meshes/Component1_Mirror___4__2.stl" scale="0.001 0.001 0.001"/>
    </geometry>
  </collision>
</link>

<link name="Foot_v3_2">
  <inertial>
    <origin xyz="0.0031278760202663736 0.004997933152016104 -0.061228443601811774" rpy="0 0 0"/>
    <mass value="0.31314451205821014"/>
    <inertia ixx="0.000443" iyy="0.000438" izz="2.5e-05" ixy="-0.0" iyz="0.0" ixz="1e-06"/>
  </inertial>
  <visual>
    <origin xyz="-0.14613 -0.106349 0.08863" rpy="0 0 0"/>
    <geometry>
      <mesh filename="file://$(find robot_description)/meshes/Foot_v3_2.stl" scale="0.001 0.001 0.001"/>
    </geometry>
    <material name="steel_satin"/>
  </visual>
  <collision>
    <origin xyz="-0.14613 -0.106349 0.08863" rpy="0 0 0"/>
    <geometry>
      <mesh filename="file://$(find robot_description)/meshes/Foot_v3_2.stl" scale="0.001 0.001 0.001"/>
    </geometry>
  </collision>
</link>

<link name="Mini_Link_v3_3">
  <inertial>
    <origin xyz="0.015778623836727845 0.001939671690657202 0.002782107313249153" rpy="0 0 0"/>
    <mass value="0.01656743535976172"/>
    <inertia ixx="0.0" iyy="2e-06" izz="2e-06" ixy="0.0" iyz="0.0" ixz="-0.0"/>
  </inertial>
  <visual>
    <origin xyz="-0.145671 -0.110329 0.007194" rpy="0 0 0"/>
    <geometry>
      <mesh filename="file://$(find robot_description)/meshes/Mini_Link_v3_3.stl" scale="0.001 0.001 0.001"/>
    </geometry>
    <material name="steel_satin"/>
  </visual>
  <collision>
    <origin xyz="-0.145671 -0.110329 0.007194" rpy="0 0 0"/>
    <geometry>
      <mesh filename="file://$(find robot_description)/meshes/Mini_Link_v3_3.stl" scale="0.001 0.001 0.001"/>
    </geometry>
  </collision>
</link>

<link name="Right_Link_v3_2">
  <inertial>
    <origin xyz="-0.03420770176182353 -0.0023405410992162062 0.05086970162616873" rpy="0 0 0"/>
    <mass value="0.16318870135962107"/>
    <inertia ixx="0.000136" iyy="0.000178" izz="4.7e-05" ixy="1e-06" iyz="-2e-06" ixz="7.2e-05"/>
  </inertial>
  <visual>
    <origin xyz="-0.145877 -0.116399 0.136063" rpy="0 0 0"/>
    <geometry>
      <mesh filename="file://$(find robot_description)/meshes/Right_Link_v3_2.stl" scale="0.001 0.001 0.001"/>
    </geometry>
    <material name="steel_satin"/>
  </visual>
  <collision>
    <origin xyz="-0.145877 -0.116399 0.136063" rpy="0 0 0"/>
    <geometry>
      <mesh filename="file://$(find robot_description)/meshes/Right_Link_v3_2.stl" scale="0.001 0.001 0.001"/>
    </geometry>
  </collision>
</link>

<link name="Mini_Link_v3_2">
  <inertial>
    <origin xyz="0.01577927520613434 0.0019395196173172813 0.002781867270160134" rpy="0 0 0"/>
    <mass value="0.01656743535976172"/>
    <inertia ixx="0.0" iyy="2e-06" izz="2e-06" ixy="0.0" iyz="0.0" ixz="-0.0"/>
  </inertial>
  <visual>
    <origin xyz="0.163164 -0.110355 0.00729" rpy="0 0 0"/>
    <geometry>
      <mesh filename="file://$(find robot_description)/meshes/Mini_Link_v3_2.stl" scale="0.001 0.001 0.001"/>
    </geometry>
    <material name="steel_satin"/>
  </visual>
  <collision>
    <origin xyz="0.163164 -0.110355 0.00729" rpy="0 0 0"/>
    <geometry>
      <mesh filename="file://$(find robot_description)/meshes/Mini_Link_v3_2.stl" scale="0.001 0.001 0.001"/>
    </geometry>
  </collision>
</link>

<link name="Right_Link_v3_1">
  <inertial>
    <origin xyz="-0.034208050392415895 -0.0023406931725567376 0.05087046158307949" rpy="0 0 0"/>
    <mass value="0.16318870135962107"/>
    <inertia ixx="0.000136" iyy="0.000178" izz="4.7e-05" ixy="1e-06" iyz="-2e-06" ixz="7.2e-05"/>
  </inertial>
  <visual>
    <origin xyz="0.162957 -0.115355 0.13616" rpy="0 0 0"/>
    <geometry>
      <mesh filename="file://$(find robot_description)/meshes/Right_Link_v3_1.stl" scale="0.001 0.001 0.001"/>
    </geometry>
    <material name="steel_satin"/>
  </visual>
  <collision>
    <origin xyz="0.162957 -0.115355 0.13616" rpy="0 0 0"/>
    <geometry>
      <mesh filename="file://$(find robot_description)/meshes/Right_Link_v3_1.stl" scale="0.001 0.001 0.001"/>
    </geometry>
  </collision>
</link>

<link name="Component1_Mirror___5__2">
  <inertial>
    <origin xyz="0.0031275273896726186 0.005052218921322613 -0.061228683644901" rpy="0 0 0"/>
    <mass value="0.31314451205821014"/>
    <inertia ixx="0.000443" iyy="0.000438" izz="2.5e-05" ixy="0.0" iyz="-0.0" ixz="1e-06"/>
  </inertial>
  <visual>
    <origin xyz="0.162704 0.115355 0.088726" rpy="0 0 0"/>
    <geometry>
      <mesh filename="file://$(find robot_description)/meshes/Component1_Mirror___5__2.stl" scale="0.001 0.001 0.001"/>
    </geometry>
    <material name="steel_satin"/>
  </visual>
  <collision>
    <origin xyz="0.162704 0.115355 0.088726" rpy="0 0 0"/>
    <geometry>
      <mesh filename="file://$(find robot_description)/meshes/Component1_Mirror___5__2.stl" scale="0.001 0.001 0.001"/>
    </geometry>
  </collision>
</link>

<link name="Mini_Link_v3_1">
  <inertial>
    <origin xyz="0.015779275206134036 0.00341048038268274 0.00278186727016009" rpy="0 0 0"/>
    <mass value="0.01656743535976172"/>
    <inertia ixx="0.0" iyy="2e-06" izz="2e-06" ixy="-0.0" iyz="-0.0" ixz="-0.0"/>
  </inertial>
  <visual>
    <origin xyz="0.163164 0.116355 0.00729" rpy="0 0 0"/>
    <geometry>
      <mesh filename="file://$(find robot_description)/meshes/Mini_Link_v3_1.stl" scale="0.001 0.001 0.001"/>
    </geometry>
    <material name="steel_satin"/>
  </visual>
  <collision>
    <origin xyz="0.163164 0.116355 0.00729" rpy="0 0 0"/>
    <geometry>
      <mesh filename="file://$(find robot_description)/meshes/Mini_Link_v3_1.stl" scale="0.001 0.001 0.001"/>
    </geometry>
  </collision>
</link>

<link name="Component2_Mirror__2">
  <inertial>
    <origin xyz="-0.03420805039241673 0.0023406931725558494 0.05087046158307951" rpy="0 0 0"/>
    <mass value="0.16318870135962107"/>
    <inertia ixx="0.000136" iyy="0.000178" izz="4.7e-05" ixy="-1e-06" iyz="2e-06" ixz="7.2e-05"/>
  </inertial>
  <visual>
    <origin xyz="0.162957 0.115355 0.13616" rpy="0 0 0"/>
    <geometry>
      <mesh filename="file://$(find robot_description)/meshes/Component2_Mirror__2.stl" scale="0.001 0.001 0.001"/>
    </geometry>
    <material name="steel_satin"/>
  </visual>
  <collision>
    <origin xyz="0.162957 0.115355 0.13616" rpy="0 0 0"/>
    <geometry>
      <mesh filename="file://$(find robot_description)/meshes/Component2_Mirror__2.stl" scale="0.001 0.001 0.001"/>
    </geometry>
  </collision>
</link>

<link name="Component1_Mirror___5__1">
  <inertial>
    <origin xyz="0.003128312429606095 0.005052066847983178 -0.06122808452425672" rpy="0 0 0"/>
    <mass value="0.31314451205821014"/>
    <inertia ixx="0.000443" iyy="0.000438" izz="2.5e-05" ixy="0.0" iyz="-0.0" ixz="1e-06"/>
  </inertial>
  <visual>
    <origin xyz="-0.146492 0.115329 0.088937" rpy="0 0 0"/>
    <geometry>
      <mesh filename="file://$(find robot_description)/meshes/Component1_Mirror___5__1.stl" scale="0.001 0.001 0.001"/>
    </geometry>
    <material name="steel_satin"/>
  </visual>
  <collision>
    <origin xyz="-0.146492 0.115329 0.088937" rpy="0 0 0"/>
    <geometry>
      <mesh filename="file://$(find robot_description)/meshes/Component1_Mirror___5__1.stl" scale="0.001 0.001 0.001"/>
    </geometry>
  </collision>
</link>

<link name="Component2_Mirror__1">
  <inertial>
    <origin xyz="-0.034208265352483225 0.0023405410992163866 0.05087006070372388" rpy="0 0 0"/>
    <mass value="0.16318870135962107"/>
    <inertia ixx="0.000136" iyy="0.000178" izz="4.7e-05" ixy="-1e-06" iyz="2e-06" ixz="7.2e-05"/>
  </inertial>
  <visual>
    <origin xyz="-0.14624 0.115329 0.13637" rpy="0 0 0"/>
    <geometry>
      <mesh filename="file://$(find robot_description)/meshes/Component2_Mirror__1.stl" scale="0.001 0.001 0.001"/>
    </geometry>
    <material name="steel_satin"/>
  </visual>
  <collision>
    <origin xyz="-0.14624 0.115329 0.13637" rpy="0 0 0"/>
    <geometry>
      <mesh filename="file://$(find robot_description)/meshes/Component2_Mirror__1.stl" scale="0.001 0.001 0.001"/>
    </geometry>
  </collision>
</link>

<link name="Mini_Link_v3_4">
  <inertial>
    <origin xyz="0.015779060246067594 -0.0019396716906562445 0.002782466390804216" rpy="0 0 0"/>
    <mass value="0.01656743535976172"/>
    <inertia ixx="0.0" iyy="2e-06" izz="2e-06" ixy="-0.0" iyz="-0.0" ixz="-0.0"/>
  </inertial>
  <visual>
    <origin xyz="-0.146033 0.110329 0.007501" rpy="0 0 0"/>
    <geometry>
      <mesh filename="file://$(find robot_description)/meshes/Mini_Link_v3_4.stl" scale="0.001 0.001 0.001"/>
    </geometry>
    <material name="steel_satin"/>
  </visual>
  <collision>
    <origin xyz="-0.146033 0.110329 0.007501" rpy="0 0 0"/>
    <geometry>
      <mesh filename="file://$(find robot_description)/meshes/Mini_Link_v3_4.stl" scale="0.001 0.001 0.001"/>
    </geometry>
  </collision>
</link>

<joint name="Revolute 1" type="revolute">
  <origin xyz="0.1184 0.076 0.0196" rpy="0 0 0"/>
  <parent link="base_link"/>
  <child link="Right_Front_Leg_Mount_v1_1"/>
  <axis xyz="1.0 0.0 -0.0"/>
  <limit upper="1.570796" lower="-1.570796" effort="100" velocity="100"/>
</joint>

<joint name="Revolute 3" type="revolute">
  <origin xyz="-0.1184 0.076 0.0196" rpy="0 0 0"/>
  <parent link="base_link"/>
  <child link="Right_Back_Leg_Mount_v1_1"/>
  <axis xyz="-1.0 -0.0 0.0"/>
  <limit upper="1.570796" lower="-1.570796" effort="100" velocity="100"/>
</joint>

<joint name="Revolute 4" type="revolute">
  <origin xyz="-0.1184 -0.076 0.0196" rpy="0 0 0"/>
  <parent link="base_link"/>
  <child link="Left_Back_Leg_Mount_v1_1"/>
  <axis xyz="-1.0 -0.0 0.0"/>
  <limit upper="1.570796" lower="-1.570796" effort="100" velocity="100"/>
</joint>

<joint name="Revolute 5" type="revolute">
  <origin xyz="0.1184 -0.076 0.0196" rpy="0 0 0"/>
  <parent link="base_link"/>
  <child link="Left_Front_Leg_Mount_v1_1"/>
  <axis xyz="1.0 0.0 -0.0"/>
  <limit upper="1.570796" lower="-1.570796" effort="100" velocity="100"/>
</joint>

<joint name="Revolute 6" type="revolute">
  <origin xyz="0.046197 0.027749 0.018658" rpy="0 0 0"/>
  <parent link="Right_Front_Leg_Mount_v1_1"/>
  <child link="Servo_Horn_v3_1"/>
  <axis xyz="0.0 1.0 0.0"/>
  <limit upper="1.570796" lower="-1.570796" effort="100" velocity="100"/>
</joint>

<joint name="Revolute 7" type="revolute">
  <origin xyz="0.025547 0.027749 -0.002342" rpy="0 0 0"/>
  <parent link="Right_Front_Leg_Mount_v1_1"/>
  <child link="Servo_Horn_v3_2"/>
  <axis xyz="0.0 1.0 0.0"/>
  <limit upper="1.570796" lower="-1.570796" effort="100" velocity="100"/>
</joint>

<joint name="Revolute 8" type="revolute">
  <origin xyz="-0.025987 0.027775 0.018562" rpy="0 0 0"/>
  <parent link="Right_Back_Leg_Mount_v1_1"/>
  <child link="Servo_Horn_v3_4"/>
  <axis xyz="0.0 1.0 0.0"/>
  <limit upper="1.570796" lower="-1.570796" effort="100" velocity="100"/>
</joint>

<joint name="Revolute 9" type="revolute">
  <origin xyz="-0.045987 0.027775 -0.002438" rpy="0 0 0"/>
  <parent link="Right_Back_Leg_Mount_v1_1"/>
  <child link="Servo_Horn_v3_3"/>
  <axis xyz="0.0 1.0 0.0"/>
  <limit upper="1.570796" lower="-1.570796" effort="100" velocity="100"/>
</joint>

<joint name="Revolute 10" type="revolute">
  <origin xyz="0.046197 -0.027749 0.018658" rpy="0 0 0"/>
  <parent link="Left_Front_Leg_Mount_v1_1"/>
  <child link="Servo_Horn_v3_5"/>
  <axis xyz="0.0 -1.0 -0.0"/>
  <limit upper="1.570796" lower="-1.570796" effort="100" velocity="100"/>
</joint>

<joint name="Revolute 11" type="revolute">
  <origin xyz="0.025547 -0.027749 -0.002342" rpy="0 0 0"/>
  <parent link="Left_Front_Leg_Mount_v1_1"/>
  <child link="Servo_Horn_v3_8"/>
  <axis xyz="0.0 -1.0 -0.0"/>
  <limit upper="1.570796" lower="-1.570796" effort="100" velocity="100"/>
</joint>

<joint name="Revolute 12" type="revolute">
  <origin xyz="-0.025987 -0.027775 0.018562" rpy="0 0 0"/>
  <parent link="Left_Back_Leg_Mount_v1_1"/>
  <child link="Servo_Horn_v3_7"/>
  <axis xyz="0.0 -1.0 -0.0"/>
  <limit upper="1.570796" lower="-1.570796" effort="100" velocity="100"/>
</joint>

<joint name="Revolute 13" type="revolute">
  <origin xyz="-0.045987 -0.027775 -0.002438" rpy="0 0 0"/>
  <parent link="Left_Back_Leg_Mount_v1_1"/>
  <child link="Servo_Horn_v3_6"/>
  <axis xyz="0.0 -1.0 0.0"/>
  <limit upper="1.570796" lower="-1.570796" effort="100" velocity="100"/>
</joint>

<joint name="Revolute 20" type="continuous">
  <origin xyz="-0.046637 0.039355 -0.002438" rpy="0 0 0"/>
  <parent link="Right_Back_Leg_Mount_v1_1"/>
  <child link="Left_Link_v4_1"/>
  <axis xyz="-0.0 -1.0 -0.0"/>
</joint>

<joint name="Revolute 23" type="continuous">
  <origin xyz="0.002333 0.0 -0.105888" rpy="0 0 0"/>
  <parent link="Left_Link_v4_1"/>
  <child link="Foot_v3_1"/>
  <axis xyz="0.0 1.0 0.0"/>
</joint>

<joint name="Revolute 25" type="continuous">
  <origin xyz="0.025397 0.039329 -0.002342" rpy="0 0 0"/>
  <parent link="Right_Front_Leg_Mount_v1_1"/>
  <child link="Left_Link_v4_2"/>
  <axis xyz="-0.0 -1.0 -0.0"/>
</joint>

<joint name="Revolute 31" type="continuous">
  <origin xyz="0.025397 -0.039329 -0.002342" rpy="0 0 0"/>
  <parent link="Left_Front_Leg_Mount_v1_1"/>
  <child link="Component1_Mirror___4__1"/>
  <axis xyz="-0.0 1.0 0.0"/>
</joint>

<joint name="Revolute 35" type="continuous">
  <origin xyz="-0.046637 -0.039355 -0.002438" rpy="0 0 0"/>
  <parent link="Left_Back_Leg_Mount_v1_1"/>
  <child link="Component1_Mirror___4__2"/>
  <axis xyz="-0.0 1.0 0.0"/>
</joint>

<joint name="Revolute 40" type="continuous">
  <origin xyz="0.002333 -0.00898 -0.105888" rpy="0 0 0"/>
  <parent link="Left_Link_v4_2"/>
  <child link="Foot_v3_2"/>
  <axis xyz="0.0 1.0 0.0"/>
</joint>

<joint name="Revolute 41" type="continuous">
  <origin xyz="0.001874 -0.005 -0.024452" rpy="0 0 0"/>
  <parent link="Left_Link_v4_2"/>
  <child link="Mini_Link_v3_3"/>
  <axis xyz="0.0 1.0 0.0"/>
</joint>

<joint name="Revolute 42" type="continuous">
  <origin xyz="-0.000253 0.01005 -0.047433" rpy="0 0 0"/>
  <parent link="Foot_v3_2"/>
  <child link="Right_Link_v3_2"/>
  <axis xyz="-0.0 -1.0 -0.0"/>
</joint>

<joint name="Revolute 43" type="continuous">
  <origin xyz="0.001873 -0.005 -0.024452" rpy="0 0 0"/>
  <parent link="Left_Link_v4_1"/>
  <child link="Mini_Link_v3_2"/>
  <axis xyz="0.0 1.0 0.0"/>
</joint>

<joint name="Revolute 44" type="continuous">
  <origin xyz="-0.000253 0.0 -0.047434" rpy="0 0 0"/>
  <parent link="Foot_v3_1"/>
  <child link="Right_Link_v3_1"/>
  <axis xyz="-0.0 -1.0 -0.0"/>
</joint>

<joint name="Revolute 45" type="continuous">
  <origin xyz="0.002333 0.0 -0.105888" rpy="0 0 0"/>
  <parent link="Component1_Mirror___4__2"/>
  <child link="Component1_Mirror___5__2"/>
  <axis xyz="0.0 -1.0 0.0"/>
</joint>

<joint name="Revolute 46" type="continuous">
  <origin xyz="0.001873 -0.001 -0.024452" rpy="0 0 0"/>
  <parent link="Component1_Mirror___4__2"/>
  <child link="Mini_Link_v3_1"/>
  <axis xyz="-0.0 1.0 -0.0"/>
</joint>

<joint name="Revolute 47" type="continuous">
  <origin xyz="-0.000253 0.0 -0.047434" rpy="0 0 0"/>
  <parent link="Component1_Mirror___5__2"/>
  <child link="Component2_Mirror__2"/>
  <axis xyz="-0.0 1.0 -0.0"/>
</joint>

<joint name="Revolute 48" type="continuous">
  <origin xyz="0.002695 0.0 -0.106195" rpy="0 0 0"/>
  <parent link="Component1_Mirror___4__1"/>
  <child link="Component1_Mirror___5__1"/>
  <axis xyz="-0.0 1.0 0.0"/>
</joint>

<joint name="Revolute 49" type="continuous">
  <origin xyz="-0.000252 0.0 -0.047433" rpy="0 0 0"/>
  <parent link="Component1_Mirror___5__1"/>
  <child link="Component2_Mirror__1"/>
  <axis xyz="-0.0 1.0 -0.0"/>
</joint>

<joint name="Revolute 50" type="continuous">
  <origin xyz="0.002236 0.005 -0.024759" rpy="0 0 0"/>
  <parent link="Component1_Mirror___4__1"/>
  <child link="Mini_Link_v3_4"/>
  <axis xyz="0.0 -1.0 -0.0"/>
</joint>

</robot>
